Workbook

Sheet Passangers Analysis
A3: Page 7 | B3: EXHIBIT 5: ORIGIN-DESTINATION DEMAND MATRIX FOR PEAK HOURS (7:30 A.M. TO 11:30 A.M.) IN NUMBER OF PASSENGERS
B5: Bus Stop Number | C5: 1 | D5: 2 | E5: 3 | F5: 4 | G5: 5 | H5: 6 | I5: 7 | J5: 8 | K5: 9 | L5: 10 | M5: 11 | N5: 12 | O5: 13 | P5: 14 | Q5: 15 | R5: 16 | S5: 17 | T5: 18 | U5: 19 | V5: 20 | W5: 21
B6: Bus Stop Name | C6: Rajiv Gandhi | D6: Mata Gujri | E6: Vishnupuri | F6: Bhanwarkuan Square | G6: Holkar Subway | H6: Navlakha Square | I6: Indra Pratima | J6: GPO | K6: Shivaji Vatika | L6: AICTSL | M6: Geeta Bhawan | N6: Palasiya | O6: Industry House | P6: LIG | Q6: Press Complex | R6: MR-9 | S6: Vijay Nagar | T6: Satya Sai | U6: Shalimar Township | V6: Scheme No. 78 | W6: Niranjanpur Square
B7: Distance* (in km) | C7: 0 | D7: 0.75 | E7: 1.2 | F7: 1.7 | G7: 2 | H7: 3 | I7: 3.3 | J7: 3.7 | K7: 4.4 | L7: 4.9 | M7: 5.4 | N7: 6.1 | O7: 6.6 | P7: 7.2 | Q7: 7.5 | R7: 8.2 | S7: 8.9 | T7: 9.5 | U7: 10.4 | V7: 10.9 | W7: 11.4 | X7: Loading | Y7: Unloading | Z7: Total people (raw)
A8: 1 | B8: Rajiv Gandhi | C8: 0 | D8: 7 | E8: 5 | F8: 52 | G8: 19 | H8: 30 | I8: 16 | J8: 71 | K8: 24 | L8: 40 | M8: 100 | N8: 80 | O8: 30 | P8: 61 | Q8: 16 | R8: 50 | S8: 39 | T8: 9 | U8: 13 | V8: 16 | W8: 23 | X8: =SUMIFS(C8:W8,$C$5:$W$5,">"&A8) -> 701 | Y8: =C29 -> 0 | Z8: =X8-Y8 -> 701 | AA8: =Z8*Results!$C$13 -> 2804 | AB8: =AA8/Results!$C$6 -> 54.980392
A9: 2 | B9: Mata Gujri | C9: 15 | D9: 0 | E9: 4 | F9: 43 | G9: 8 | H9: 24 | I9: 14 | J9: 24 | K9: 15 | L9: 15 | M9: 43 | N9: 37 | O9: 12 | P9: 23 | Q9: 5 | R9: 30 | S9: 22 | T9: 8 | U9: 9 | V9: 11 | W9: 10 | X9: =SUMIFS(C9:W9,$C$5:$W$5,">"&A9) -> 357 | Y9: =D29 -> 7 | Z9: =Z8+X9-Y9 -> 1051 | AA9: =Z9*Results!$C$13 -> 4204 | AB9: =AA9/Results!$C$6 -> 82.431373
A10: 3 | B10: Vishnupuri | C10: 8 | D10: 6 | E10: 0 | F10: 21 | G10: 10 | H10: 17 | I10: 9 | J10: 25 | K10: 8 | L10: 16 | M10: 45 | N10: 31 | O10: 0 | P10: 20 | Q10: 6 | R10: 21 | S10: 16 | T10: 5 | U10: 4 | V10: 4 | W10: 8 | X10: =SUMIFS(C10:W10,$C$5:$W$5,">"&A10) -> 266 | Y10: =E29 -> 9 | Z10: =Z9+X10-Y10 -> 1308 | AA10: =Z10*Results!$C$13 -> 5232 | AB10: =AA10/Results!$C$6 -> 102.58824
A11: 4 | B11: Bhanwarkuan Square | C11: 24 | D11: 11 | E11: 7 | F11: 0 | G11: 22 | H11: 53 | I11: 27 | J11: 119 | K11: 32 | L11: 73 | M11: 232 | N11: 176 | O11: 40 | P11: 169 | Q11: 13 | R11: 91 | S11: 82 | T11: 12 | U11: 18 | V11: 20 | W11: 26 | X11: =SUMIFS(C11:W11,$C$5:$W$5,">"&A11) -> 1205 | Y11: =F29 -> 116 | Z11: =Z10+X11-Y11 -> 2397 | AA11: =Z11*Results!$C$13 -> 9588 | AB11: =AA11/Results!$C$6 -> 188
A12: 5 | B12: Holkar Subway | C12: 8 | D12: 4 | E12: 3 | F12: 31 | G12: 0 | H12: 12 | I12: 5 | J12: 18 | K12: 10 | L12: 11 | M12: 26 | N12: 38 | O12: 14 | P12: 30 | Q12: 4 | R12: 9 | S12: 12 | T12: 5 | U12: 6 | V12: 6 | W12: 5 | X12: =SUMIFS(C12:W12,$C$5:$W$5,">"&A12) -> 211 | Y12: =G29 -> 59 | Z12: =Z11+X12-Y12 -> 2549 | AA12: =Z12*Results!$C$13 -> 10196 | AB12: =AA12/Results!$C$6 -> 199.92157
A13: 6 | B13: Navlakha Square | C13: 25 | D13: 20 | E13: 20 | F13: 182 | G13: 47 | H13: 0 | I13: 66 | J13: 145 | K13: 33 | L13: 58 | M13: 299 | N13: 316 | O13: 58 | P13: 223 | Q13: 29 | R13: 201 | S13: 133 | T13: 24 | U13: 23 | V13: 42 | W13: 46 | X13: =SUMIFS(C13:W13,$C$5:$W$5,">"&A13) -> 1696 | Y13: =H29 -> 136 | Z13: =Z12+X13-Y13 -> 4109 | AA13: =Z13*Results!$C$13 -> 16436 | AB13: =AA13/Results!$C$6 -> 322.27451
A14: 7 | B14: Indra Pratima | C14: 18 | D14: 11 | E14: 9 | F14: 66 | G14: 20 | H14: 52 | I14: 0 | J14: 69 | K14: 21 | L14: 47 | M14: 89 | N14: 78 | O14: 39 | P14: 87 | Q14: 13 | R14: 55 | S14: 36 | T14: 15 | U14: 9 | V14: 20 | W14: 25 | X14: =SUMIFS(C14:W14,$C$5:$W$5,">"&A14) -> 603 | Y14: =I29 -> 137 | Z14: =Z13+X14-Y14 -> 4575 | AA14: =Z14*Results!$C$13 -> 18300 | AB14: =AA14/Results!$C$6 -> 358.82353
A15: 8 | B15: GPO | C15: 17 | D15: 11 | E15: 6 | F15: 127 | G15: 21 | H15: 72 | I15: 16 | J15: 0 | K15: 30 | L15: 43 | M15: 152 | N15: 131 | O15: 24 | P15: 140 | Q15: 12 | R15: 79 | S15: 67 | T15: 8 | U15: 11 | V15: 13 | W15: 15 | X15: =SUMIFS(C15:W15,$C$5:$W$5,">"&A15) -> 725 | Y15: =J29 -> 471 | Z15: =Z14+X15-Y15 -> 4829 | AA15: =Z15*Results!$C$13 -> 19316 | AB15: =AA15/Results!$C$6 -> 378.7451
A16: 9 | B16: Shivaji Vatika | C16: 6 | D16: 4 | E16: 3 | F16: 26 | G16: 14 | H16: 13 | I16: 7 | J16: 31 | K16: 0 | L16: 11 | M16: 32 | N16: 20 | O16: 15 | P16: 21 | Q16: 4 | R16: 11 | S16: 8 | T16: 4 | U16: 6 | V16: 9 | W16: 7 | X16: =SUMIFS(C16:W16,$C$5:$W$5,">"&A16) -> 148 | Y16: =K29 -> 173 | Z16: =Z15+X16-Y16 -> 4804 | AA16: =Z16*Results!$C$13 -> 19216 | AB16: =AA16/Results!$C$6 -> 376.78431
A17: 10 | B17: AICTSL | C17: 14 | D17: 5 | E17: 3 | F17: 57 | G17: 19 | H17: 20 | I17: 23 | J17: 39 | K17: 18 | L17: 0 | M17: 61 | N17: 43 | O17: 18 | P17: 47 | Q17: 7 | R17: 27 | S17: 21 | T17: 5 | U17: 6 | V17: 16 | W17: 10 | X17: =SUMIFS(C17:W17,$C$5:$W$5,">"&A17) -> 261 | Y17: =L29 -> 314 | Z17: =Z16+X17-Y17 -> 4751 | AA17: =Z17*Results!$C$13 -> 19004 | AB17: =AA17/Results!$C$6 -> 372.62745
A18: 11 | B18: Geeta Bhawan | C18: 21 | D18: 10 | E18: 9 | F18: 246 | G18: 34 | H18: 75 | I18: 28 | J18: 102 | K18: 36 | L18: 49 | M18: 0 | N18: 231 | O18: 53 | P18: 169 | Q18: 22 | R18: 88 | S18: 36 | T18: 12 | U18: 13 | V18: 17 | W18: 17 | X18: =SUMIFS(C18:W18,$C$5:$W$5,">"&A18) -> 658 | Y18: =M29 -> 1079 | Z18: =Z17+X18-Y18 -> 4330 | AA18: =Z18*Results!$C$13 -> 17320 | AB18: =AA18/Results!$C$6 -> 339.60784
A19: 12 | B19: Palasiya | C19: 30 | D19: 13 | E19: 10 | F19: 243 | G19: 33 | H19: 119 | I19: 31 | J19: 128 | K19: 26 | L19: 44 | M19: 205 | N19: 0 | O19: 35 | P19: 150 | Q19: 12 | R19: 112 | S19: 82 | T19: 8 | U19: 13 | V19: 20 | W19: 22 | X19: =SUMIFS(C19:W19,$C$5:$W$5,">"&A19) -> 454 | Y19: =N29 -> 1181 | Z19: =Z18+X19-Y19 -> 3603 | AA19: =Z19*Results!$C$13 -> 14412 | AB19: =AA19/Results!$C$6 -> 282.58824
A20: 13 | B20: Industry House | C20: 9 | D20: 5 | E20: 0 | F20: 44 | G20: 14 | H20: 21 | I20: 10 | J20: 40 | K20: 10 | L20: 26 | M20: 53 | N20: 42 | O20: 0 | P20: 41 | Q20: 8 | R20: 18 | S20: 13 | T20: 6 | U20: 5 | V20: 10 | W20: 9 | X20: =SUMIFS(C20:W20,$C$5:$W$5,">"&A20) -> 110 | Y20: =O29 -> 338 | Z20: =Z19+X20-Y20 -> 3375 | AA20: =Z20*Results!$C$13 -> 13500 | AB20: =AA20/Results!$C$6 -> 264.70588
A21: 14 | B21: LIG | C21: 21 | D21: 11 | E21: 9 | F21: 141 | G21: 22 | H21: 77 | I21: 26 | J21: 95 | K21: 31 | L21: 44 | M21: 186 | N21: 172 | O21: 43 | P21: 0 | Q21: 15 | R21: 97 | S21: 75 | T21: 5 | U21: 10 | V21: 19 | W21: 17 | X21: =SUMIFS(C21:W21,$C$5:$W$5,">"&A21) -> 238 | Y21: =P29 -> 1181 | Z21: =Z20+X21-Y21 -> 2432 | AA21: =Z21*Results!$C$13 -> 9728 | AB21: =AA21/Results!$C$6 -> 190.7451
A22: 15 | B22: Press Complex | C22: 13 | D22: 7 | E22: 6 | F22: 43 | G22: 25 | H22: 35 | I22: 18 | J22: 32 | K22: 18 | L22: 24 | M22: 46 | N22: 51 | O22: 15 | P22: 48 | Q22: 0 | R22: 26 | S22: 28 | T22: 11 | U22: 10 | V22: 10 | W22: 13 | X22: =SUMIFS(C22:W22,$C$5:$W$5,">"&A22) -> 98 | Y22: =Q29 -> 166 | Z22: =Z21+X22-Y22 -> 2364 | AA22: =Z22*Results!$C$13 -> 9456 | AB22: =AA22/Results!$C$6 -> 185.41176
A23: 16 | B23: MR-9 | C23: 32 | D23: 20 | E23: 17 | F23: 150 | G23: 40 | H23: 220 | I23: 60 | J23: 146 | K23: 27 | L23: 58 | M23: 364 | N23: 188 | O23: 77 | P23: 268 | Q23: 26 | R23: 0 | S23: 124 | T23: 26 | U23: 30 | V23: 37 | W23: 50 | X23: =SUMIFS(C23:W23,$C$5:$W$5,">"&A23) -> 267 | Y23: =R29 -> 915 | Z23: =Z22+X23-Y23 -> 1716 | AA23: =Z23*Results!$C$13 -> 6864 | AB23: =AA23/Results!$C$6 -> 134.58824
A24: 17 | B24: Vijay Nagar | C24: 30 | D24: 23 | E24: 13 | F24: 220 | G24: 39 | H24: 122 | I24: 46 | J24: 201 | K24: 50 | L24: 49 | M24: 174 | N24: 287 | O24: 57 | P24: 214 | Q24: 27 | R24: 162 | S24: 0 | T24: 16 | U24: 28 | V24: 45 | W24: 43 | X24: =SUMIFS(C24:W24,$C$5:$W$5,">"&A24) -> 132 | Y24: =S29 -> 794 | Z24: =Z23+X24-Y24 -> 1054 | AA24: =Z24*Results!$C$13 -> 4216 | AB24: =AA24/Results!$C$6 -> 82.666667
A25: 18 | B25: Satya Sai | C25: 7 | D25: 6 | E25: 9 | F25: 38 | G25: 16 | H25: 21 | I25: 12 | J25: 23 | K25: 11 | L25: 16 | M25: 44 | N25: 29 | O25: 18 | P25: 27 | Q25: 4 | R25: 22 | S25: 15 | T25: 0 | U25: 12 | V25: 10 | W25: 10 | X25: =SUMIFS(C25:W25,$C$5:$W$5,">"&A25) -> 32 | Y25: =T29 -> 179 | Z25: =Z24+X25-Y25 -> 907 | AA25: =Z25*Results!$C$13 -> 3628 | AB25: =AA25/Results!$C$6 -> 71.137255
A26: 19 | B26: Shalimar Township | C26: 15 | D26: 8 | E26: 7 | F26: 30 | G26: 20 | H26: 19 | I26: 11 | J26: 43 | K26: 13 | L26: 25 | M26: 56 | N26: 39 | O26: 12 | P26: 50 | Q26: 12 | R26: 32 | S26: 24 | T26: 7 | U26: 0 | V26: 8 | W26: 16 | X26: =SUMIFS(C26:W26,$C$5:$W$5,">"&A26) -> 24 | Y26: =U29 -> 226 | Z26: =Z25+X26-Y26 -> 705 | AA26: =Z26*Results!$C$13 -> 2820 | AB26: =AA26/Results!$C$6 -> 55.294118
A27: 20 | B27: Scheme No. 78 | C27: 26 | D27: 11 | E27: 7 | F27: 85 | G27: 25 | H27: 42 | I27: 13 | J27: 36 | K27: 17 | L27: 34 | M27: 41 | N27: 70 | O27: 36 | P27: 71 | Q27: 10 | R27: 45 | S27: 38 | T27: 8 | U27: 14 | V27: 0 | W27: 22 | X27: =SUMIFS(C27:W27,$C$5:$W$5,">"&A27) -> 22 | Y27: =V29 -> 333 | Z27: =Z26+X27-Y27 -> 394 | AA27: =Z27*Results!$C$13 -> 1576 | AB27: =AA27/Results!$C$6 -> 30.901961
A28: 21 | B28: Niranjanpur Square | C28: 20 | D28: 9 | E28: 9 | F28: 63 | G28: 21 | H28: 29 | I28: 27 | J28: 56 | K28: 16 | L28: 28 | M28: 85 | N28: 45 | O28: 17 | P28: 51 | Q28: 16 | R28: 45 | S28: 40 | T28: 10 | U28: 17 | V28: 25 | W28: 0 | X28: =SUMIFS(C28:W28,$C$5:$W$5,">"&A28) -> 0 | Y28: =W29 -> 394 | Z28: =Z27+X28-Y28 -> 0 | AA28: =Z28*Results!$C$13 -> 0 | AB28: =AA28/Results!$C$6 -> 0
C29: {=SUM(IF($A$8:$A$28<C$5,C8:C28,0))} -> 0 | D29: {=SUM(IF($A$8:$A$28<D$5,D8:D28,0))} -> 7 | E29: {=SUM(IF($A$8:$A$28<E$5,E8:E28,0))} -> 9 | F29: {=SUM(IF($A$8:$A$28<F$5,F8:F28,0))} -> 116 | G29: {=SUM(IF($A$8:$A$28<G$5,G8:G28,0))} -> 59 | H29: {=SUM(IF($A$8:$A$28<H$5,H8:H28,0))} -> 136 | I29: {=SUM(IF($A$8:$A$28<I$5,I8:I28,0))} -> 137 | J29: {=SUM(IF($A$8:$A$28<J$5,J8:J28,0))} -> 471 | ... W29: {=SUM(IF($A$8:$A$28<W$5,W8:W28,0))} -> 394
A31: Note: *distance is measured from the origin (Rajiv Gandhi) to the specified stop; the number of passengers is the total number of passengers travelling between an origin
A32: (row) and destination (column) over the measured period; km = kilometres; AICTSL = Atal Indore City Transport Service Limited
A33: Source: Company files.
A35: Page 8 | B35: EXHIBIT 6: ORIGIN-DESTINATION DEMAND MATRIX FOR NON-PEAK HOURS (11:30 A.M. TO 14:30 P.M.) IN NUMBER OF PASSENGERS
B37: Bus Stop Number | C37: 1 | D37: 2 | E37: 3 | F37: 4 | G37: 5 | H37: 6 | I37: 7 | J37: 8 | K37: 9 | L37: 10 | M37: 11 | N37: 12 | O37: 13 | P37: 14 | Q37: 15 | R37: 16 | S37: 17 | T37: 18 | U37: 19 | V37: 20 | W37: 21
B38: Bus Stop Name | C38: Rajiv Gandhi | D38: Mata Gujri | E38: Vishnupuri | F38: Bhanwarkuan Square | G38: Holkar Subway | H38: Navlakha Square | I38: Indra Pratima | J38: GPO | K38: Shivaji Vatika | L38: AICTSL | M38: Geeta Bhawan | N38: Palasiya | O38: Industry House | P38: LIG | Q38: Press Complex | R38: MR-9 | S38: Vijay Nagar | T38: Satya Sai | U38: Shalimar Township | V38: Scheme No. 78 | W38: Niranjanpur Square
B39: Distance* (in km) | C39: 0 | D39: 0.75 | E39: 1.2 | F39: 1.7 | G39: 2 | H39: 3 | I39: 3.3 | J39: 3.7 | K39: 4.4 | L39: 4.9 | M39: 5.4 | N39: 6.1 | O39: 6.6 | P39: 7.2 | Q39: 7.5 | R39: 8.2 | S39: 8.9 | T39: 9.5 | U39: 10.4 | V39: 10.9 | W39: 11.4 | X39: Loading | Y39: Unloading | Z39: Total people (raw)
A40: 1 | B40: Rajiv Gandhi | C40: 0 | D40: 2 | E40: 1 | F40: 10 | G40: 3 | H40: 8 | I40: 5 | J40: 5 | K40: 4 | L40: 4 | M40: 8 | N40: 16 | O40: 6 | P40: 8 | Q40: 3 | R40: 10 | S40: 8 | T40: 3 | U40: 4 | V40: 7 | W40: 4 | X40: =SUMIFS(C40:W40,$C$37:$W$37,">"&A40) -> 119 | Y40: =C61 -> 0 | Z40: =X40-Y40 -> 119 | AA40: =Z40*Results!$C$13 -> 476 | AB40: =AA40/Results!$C$6 -> 9.3333333
A41: 2 | B41: Mata Gujri | C41: 2 | D41: 0 | E41: 2 | F41: 5 | G41: 1 | H41: 5 | I41: 3 | J41: 6 | K41: 2 | L41: 4 | M41: 4 | N41: 7 | O41: 3 | P41: 5 | Q41: 2 | R41: 7 | S41: 4 | T41: 3 | U41: 3 | V41: 2 | W41: 3 | X41: =SUMIFS(C41:W41,$C$37:$W$37,">"&A41) -> 71 | Y41: =D61 -> 2 | Z41: =Z40+X41-Y41 -> 188 | AA41: =Z41*Results!$C$13 -> 752 | AB41: =AA41/Results!$C$6 -> 14.745098
A42: 3 | B42: Vishnupuri | C42: 2 | D42: 1 | E42: 0 | F42: 6 | G42: 2 | H42: 4 | I42: 3 | J42: 4 | K42: 2 | L42: 3 | M42: 3 | N42: 7 | O42: 0 | P42: 5 | Q42: 1 | R42: 3 | S42: 4 | T42: 1 | U42: 2 | V42: 2 | W42: 2 | X42: =SUMIFS(C42:W42,$C$37:$W$37,">"&A42) -> 54 | Y42: =E61 -> 3 | Z42: =Z41+X42-Y42 -> 239 | AA42: =Z42*Results!$C$13 -> 956 | AB42: =AA42/Results!$C$6 -> 18.745098
A43: 4 | B43: Bhanwarkuan Square | C43: 12 | D43: 7 | E43: 5 | F43: 0 | G43: 6 | H43: 34 | I43: 12 | J43: 34 | K43: 9 | L43: 14 | M43: 44 | N43: 54 | O43: 10 | P43: 47 | Q43: 8 | R43: 47 | S43: 40 | T43: 7 | U43: 6 | V43: 17 | W43: 12 | X43: =SUMIFS(C43:W43,$C$37:$W$37,">"&A43) -> 401 | Y43: =F61 -> 21 | Z43: =Z42+X43-Y43 -> 619 | AA43: =Z43*Results!$C$13 -> 2476 | AB43: =AA43/Results!$C$6 -> 48.54902
A44: 5 | B44: Holkar Subway | C44: 3 | D44: 2 | E44: 2 | F44: 8 | G44: 0 | H44: 5 | I44: 4 | J44: 6 | K44: 2 | L44: 5 | M44: 4 | N44: 7 | O44: 2 | P44: 10 | Q44: 1 | R44: 4 | S44: 4 | T44: 2 | U44: 2 | V44: 4 | W44: 4 | X44: =SUMIFS(C44:W44,$C$37:$W$37,">"&A44) -> 66 | Y44: =G61 -> 12 | Z44: =Z43+X44-Y44 -> 673 | AA44: =Z44*Results!$C$13 -> 2692 | AB44: =AA44/Results!$C$6 -> 52.784314
A45: 6 | B45: Navlakha Square | C45: 10 | D45: 6 | E45: 3 | F45: 60 | G45: 6 | H45: 0 | I45: 16 | J45: 32 | K45: 5 | L45: 13 | M45: 56 | N45: 32 | O45: 13 | P45: 31 | Q45: 7 | R45: 70 | S45: 21 | T45: 4 | U45: 7 | V45: 9 | W45: 5 | X45: =SUMIFS(C45:W45,$C$37:$W$37,">"&A45) -> 321 | Y45: =H61 -> 56 | Z45: =Z44+X45-Y45 -> 938 | AA45: =Z45*Results!$C$13 -> 3752 | AB45: =AA45/Results!$C$6 -> 73.568627
A46: 7 | B46: Indra Pratima | C46: 8 | D46: 3 | E46: 1 | F46: 17 | G46: 3 | H46: 13 | I46: 0 | J46: 11 | K46: 1 | L46: 6 | M46: 11 | N46: 13 | O46: 3 | P46: 17 | Q46: 5 | R46: 15 | S46: 7 | T46: 4 | U46: 4 | V46: 5 | W46: 5 | X46: =SUMIFS(C46:W46,$C$37:$W$37,">"&A46) -> 107 | Y46: =I61 -> 43 | Z46: =Z45+X46-Y46 -> 1002 | AA46: =Z46*Results!$C$13 -> 4008 | AB46: =AA46/Results!$C$6 -> 78.588235
...

Sheet Normal Distribution simulation
A3: Page 7 | B3: EXHIBIT 5: ORIGIN-DESTINATION DEMAND MATRIX FOR PEAK HOURS (7:30 A.M. TO 11:30 A.M.) IN NUMBER OF PASSENGERS
B5: Bus Stop Number | C5: 1 | D5: 2 | E5: 3 | F5: 4 | G5: 5 | H5: 6 | I5: 7 | J5: 8 | K5: 9 | L5: 10 | M5: 11 | N5: 12 | O5: 13 | P5: 14 | Q5: 15 | R5: 16 | S5: 17 | T5: 18 | U5: 19 | V5: 20 | W5: 21
B6: Bus Stop Name | C6: Rajiv Gandhi | D6: Mata Gujri | E6: Vishnupuri | F6: Bhanwarkuan Square | G6: Holkar Subway | H6: Navlakha Square | I6: Indra Pratima | J6: GPO | K6: Shivaji Vatika | L6: AICTSL | M6: Geeta Bhawan | N6: Palasiya | O6: Industry House | P6: LIG | Q6: Press Complex | R6: MR-9 | S6: Vijay Nagar | T6: Satya Sai | U6: Shalimar Township | V6: Scheme No. 78 | W6: Niranjanpur Square
B7: Distance* (in km) | C7: 0 | D7: 0.75 | E7: 1.2 | F7: 1.7 | G7: 2 | H7: 3 | I7: 3.3 | J7: 3.7 | K7: 4.4 | L7: 4.9 | M7: 5.4 | N7: 6.1 | O7: 6.6 | P7: 7.2 | Q7: 7.5 | R7: 8.2 | S7: 8.9 | T7: 9.5 | U7: 10.4 | V7: 10.9 | W7: 11.4 | X7: Northbound Loading | Y7: Northbound Unloading | Z7: Northbound Total people (raw) | AA7: Northbound Per hour | AB7: Buses per hour | AD7: Southbound loading | AE7: Southbound unloading | AF7: Southmound total | AG7: Southboound per hour | AH7: Buses per hour
A8: 1 | B8: Rajiv Gandhi | C8: =IFERROR(NORMINV(RAND(),'Passangers Analysis'!C8,'Passangers Analysis'!C8*0.2),0) -> 0 | D8: =IFERROR(NORMINV(RAND(),'Passangers Analysis'!D8,'Passangers Analysis'!D8*0.2),0) -> 6.5922689 | E8: =IFERROR(NORMINV(RAND(),'Passangers Analysis'!E8,'Passangers Analysis'!E8*0.2),0) -> 5.1824329 | F8: =IFERROR(NORMINV(RAND(),'Passangers Analysis'!F8,'Passangers Analysis'!F8*0.2),0) -> 48.61048 | G8: =IFERROR(NORMINV(RAND(),'Passangers Analysis'!G8,'Passangers Analysis'!G8*0.2),0) -> 19.409285 | H8: =IFERROR(NORMINV(RAND(),'Passangers Analysis'!H8,'Passangers Analysis'!H8*0.2),0) -> 26.414318 | I8: =IFERROR(NORMINV(RAND(),'Passangers Analysis'!I8,'Passangers Analysis'!I8*0.2),0) -> 8.097924 | J8: =IFERROR(NORMINV(RAND(),'Passangers Analysis'!J8,'Passangers Analysis'!J8*0.2),0) -> 71.306012 | ... W8: =IFERROR(NORMINV(RAND(),'Passangers Analysis'!W8,'Passangers Analysis'!W8*0.2),0) -> 22.218165 | X8: =SUMIFS(C8:W8,$C$5:$W$5,">"&A8) -> 640.94188 | Y8: =C29 -> 0 | Z8: =X8-Y8 -> 640.94188 | AA8: =Z8/Results!$C$13 -> 160.23547 | AB8: =AA8/Results!$C$6 -> 3.141872 | AD8: =SUMIFS(C8:W8,$C$5:$W$5,"<"&A8) -> 0 | AE8: =C30 -> 340.1262 | AF8: =AF9+AD8-AE8 -> 0 | AG8: =AF8/Results!$C$13 -> 0 | AH8: =AG8/Results!$C$6 -> 0
A9: 2 | B9: Mata Gujri | C9: =IFERROR(NORMINV(RAND(),'Passangers Analysis'!C9,'Passangers Analysis'!C9*0.2),0) -> 15.856549 | D9: =IFERROR(NORMINV(RAND(),'Passangers Analysis'!D9,'Passangers Analysis'!D9*0.2),0) -> 0 | E9: =IFERROR(NORMINV(RAND(),'Passangers Analysis'!E9,'Passangers Analysis'!E9*0.2),0) -> 3.4865605 | F9: =IFERROR(NORMINV(RAND(),'Passangers Analysis'!F9,'Passangers Analysis'!F9*0.2),0) -> 56.885366 | G9: =IFERROR(NORMINV(RAND(),'Passangers Analysis'!G9,'Passangers Analysis'!G9*0.2),0) -> 7.9967215 | H9: =IFERROR(NORMINV(RAND(),'Passangers Analysis'!H9,'Passangers Analysis'!H9*0.2),0) -> 26.138317 | I9: =IFERROR(NORMINV(RAND(),'Passangers Analysis'!I9,'Passangers Analysis'!I9*0.2),0) -> 13.927357 | J9: =IFERROR(NORMINV(RAND(),'Passangers Analysis'!J9,'Passangers Analysis'!J9*0.2),0) -> 22.075801 | ... W9: =IFERROR(NORMINV(RAND(),'Passangers Analysis'!W9,'Passangers Analysis'!W9*0.2),0) -> 7.2761186 | X9: =SUMIFS(C9:W9,$C$5:$W$5,">"&A9) -> 363.88754 | Y9: =D29 -> 6.5922689 | Z9: =Z8+X9-Y9 -> 998.23715 | AA9: =Z9/Results!$C$13 -> 249.55929 | AB9: =AA9/Results!$C$6 -> 4.8933194 | AD9: =SUMIFS(C9:W9,$C$5:$W$5,"<"&A9) -> 15.856549 | AE9: =D30 -> 196.03025 | AF9: =AF10+AD9-AE9 -> 340.1262 | AG9: =AF9/Results!$C$13 -> 85.031549 | AH9: =AG9/Results!$C$6 -> 1.6672853
A10: 3 | B10: Vishnupuri | C10: =IFERROR(NORMINV(RAND(),'Passangers Analysis'!C10,'Passangers Analysis'!C10*0.2),0) -> 8.502987 | D10: =IFERROR(NORMINV(RAND(),'Passangers Analysis'!D10,'Passangers Analysis'!D10*0.2),0) -> 2.9049076 | E10: =IFERROR(NORMINV(RAND(),'Passangers Analysis'!E10,'Passangers Analysis'!E10*0.2),0) -> 0 | F10: =IFERROR(NORMINV(RAND(),'Passangers Analysis'!F10,'Passangers Analysis'!F10*0.2),0) -> 27.336889 | G10: =IFERROR(NORMINV(RAND(),'Passangers Analysis'!G10,'Passangers Analysis'!G10*0.2),0) -> 9.4634007 | H10: =IFERROR(NORMINV(RAND(),'Passangers Analysis'!H10,'Passangers Analysis'!H10*0.2),0) -> 21.221708 | I10: =IFERROR(NORMINV(RAND(),'Passangers Analysis'!I10,'Passangers Analysis'!I10*0.2),0) -> 6.5053695 | J10: =IFERROR(NORMINV(RAND(),'Passangers Analysis'!J10,'Passangers Analysis'!J10*0.2),0) -> 24.876674 | ... W10: =IFERROR(NORMINV(RAND(),'Passangers Analysis'!W10,'Passangers Analysis'!W10*0.2),0) -> 6.8285483 | X10: =SUMIFS(C10:W10,$C$5:$W$5,">"&A10) -> 257.34197 | Y10: =E29 -> 8.6689934 | Z10: =Z9+X10-Y10 -> 1246.9101 | AA10: =Z10/Results!$C$13 -> 311.72753 | AB10: =AA10/Results!$C$6 -> 6.1123045 | AD10: =SUMIFS(C10:W10,$C$5:$W$5,"<"&A10) -> 11.407895 | AE10: =E30 -> 137.63534 | AF10: =AF11+AD10-AE10 -> 520.2999 | AG10: =AF10/Results!$C$13 -> 130.07498 | AH10: =AG10/Results!$C$6 -> 2.5504897
A11: 4 | B11: Bhanwarkuan Square | C11: =IFERROR(NORMINV(RAND(),'Passangers Analysis'!C11,'Passangers Analysis'!C11*0.2),0) -> 21.045545 | D11: =IFERROR(NORMINV(RAND(),'Passangers Analysis'!D11,'Passangers Analysis'!D11*0.2),0) -> 12.865903 | E11: =IFERROR(NORMINV(RAND(),'Passangers Analysis'!E11,'Passangers Analysis'!E11*0.2),0) -> 8.1831717 | F11: =IFERROR(NORMINV(RAND(),'Passangers Analysis'!F11,'Passangers Analysis'!F11*0.2),0) -> 0 | G11: =IFERROR(NORMINV(RAND(),'Passangers Analysis'!G11,'Passangers Analysis'!G11*0.2),0) -> 17.549884 | H11: =IFERROR(NORMINV(RAND(),'Passangers Analysis'!H11,'Passangers Analysis'!H11*0.2),0) -> 30.211494 | I11: =IFERROR(NORMINV(RAND(),'Passangers Analysis'!I11,'Passangers Analysis'!I11*0.2),0) -> 30.078604 | J11: =IFERROR(NORMINV(RAND(),'Passangers Analysis'!J11,'Passangers Analysis'!J11*0.2),0) -> 127.77428 | ... W11: =IFERROR(NORMINV(RAND(),'Passangers Analysis'!W11,'Passangers Analysis'!W11*0.2),0) -> 23.412088 | X11: =SUMIFS(C11:W11,$C$5:$W$5,">"&A11) -> 1273.3413 | Y11: =F29 -> 132.83273 | Z11: =Z10+X11-Y11 -> 2387.4187 | AA11: =Z11/Results!$C$13 -> 596.85466 | AB11: =AA11/Results!$C$6 -> 11.703033 | AD11: =SUMIFS(C11:W11,$C$5:$W$5,"<"&A11) -> 42.094619 | AE11: =F30 -> 1714.5743 | AF11: =AF12+AD11-AE11 -> 646.52735 | AG11: =AF11/Results!$C$13 -> 161.63184 | AH11: =AG11/Results!$C$6 -> 3.1692517
A12: 5 | B12: Holkar Subway | C12: =IFERROR(NORMINV(RAND(),'Passangers Analysis'!C12,'Passangers Analysis'!C12*0.2),0) -> 6.2737257 | D12: =IFERROR(NORMINV(RAND(),'Passangers Analysis'!D12,'Passangers Analysis'!D12*0.2),0) -> 5.4646314 | E12: =IFERROR(NORMINV(RAND(),'Passangers Analysis'!E12,'Passangers Analysis'!E12*0.2),0) -> 3.1978173 | F12: =IFERROR(NORMINV(RAND(),'Passangers Analysis'!F12,'Passangers Analysis'!F12*0.2),0) -> 30.329794 | G12: =IFERROR(NORMINV(RAND(),'Passangers Analysis'!G12,'Passangers Analysis'!G12*0.2),0) -> 0 | H12: =IFERROR(NORMINV(RAND(),'Passangers Analysis'!H12,'Passangers Analysis'!H12*0.2),0) -> 8.2599805 | I12: =IFERROR(NORMINV(RAND(),'Passangers Analysis'!I12,'Passangers Analysis'!I12*0.2),0) -> 5.8950416 | J12: =IFERROR(NORMINV(RAND(),'Passangers Analysis'!J12,'Passangers Analysis'!J12*0.2),0) -> 17.709647 | ... W12: =IFERROR(NORMINV(RAND(),'Passangers Analysis'!W12,'Passangers Analysis'!W12*0.2),0) -> 4.841169 | X12: =SUMIFS(C12:W12,$C$5:$W$5,">"&A12) -> 198.75075 | Y12: =G29 -> 54.419291 | Z12: =Z11+X12-Y12 -> 2531.7501 | AA12: =Z12/Results!$C$13 -> 632.93753 | AB12: =AA12/Results!$C$6 -> 12.41054 | AD12: =SUMIFS(C12:W12,$C$5:$W$5,"<"&A12) -> 45.265968 | AE12: =G30 -> 423.42279 | AF12: =AF13+AD12-AE12 -> 2319.0071 | AG12: =AF12/Results!$C$13 -> 579.75177 | AH12: =AG12/Results!$C$6 -> 11.367682
A13: 6 | B13: Navlakha Square | C13: =IFERROR(NORMINV(RAND(),'Passangers Analysis'!C13,'Passangers Analysis'!C13*0.2),0) -> 22.550391 | D13: =IFERROR(NORMINV(RAND(),'Passangers Analysis'!D13,'Passangers Analysis'!D13*0.2),0) -> 24.956799 | E13: =IFERROR(NORMINV(RAND(),'Passangers Analysis'!E13,'Passangers Analysis'!E13*0.2),0) -> 15.887684 | F13: =IFERROR(NORMINV(RAND(),'Passangers Analysis'!F13,'Passangers Analysis'!F13*0.2),0) -> 195.56821 | G13: =IFERROR(NORMINV(RAND(),'Passangers Analysis'!G13,'Passangers Analysis'!G13*0.2),0) -> 43.105293 | H13: =IFERROR(NORMINV(RAND(),'Passangers Analysis'!H13,'Passangers Analysis'!H13*0.2),0) -> 0 | I13: =IFERROR(NORMINV(RAND(),'Passangers Analysis'!I13,'Passangers Analysis'!I13*0.2),0) -> 34.603162 | J13: =IFERROR(NORMINV(RAND(),'Passangers Analysis'!J13,'Passangers Analysis'!J13*0.2),0) -> 212.32911 | ... W13: =IFERROR(NORMINV(RAND(),'Passangers Analysis'!W13,'Passangers Analysis'!W13*0.2),0) -> 47.70675 | X13: =SUMIFS(C13:W13,$C$5:$W$5,">"&A13) -> 1847.2301 | Y13: =H29 -> 112.24582 | Z13: =Z12+X13-Y13 -> 4266.7344 | AA13: =Z13/Results!$C$13 -> 1066.6836 | AB13: =AA13/Results!$C$6 -> 20.915365 | AD13: =SUMIFS(C13:W13,$C$5:$W$5,"<"&A13) -> 302.06838 | AE13: =H30 -> 827.96513 | AF13: =AF14+AD13-AE13 -> 2697.1639 | AG13: =AF13/Results!$C$13 -> 674.29097 | AH13: =AG13/Results!$C$6 -> 13.221392
A14: 7 | B14: Indra Pratima | C14: =IFERROR(NORMINV(RAND(),'Passangers Analysis'!C14,'Passangers Analysis'!C14*0.2),0) -> 20.457523 | D14: =IFERROR(NORMINV(RAND(),'Passangers Analysis'!D14,'Passangers Analysis'!D14*0.2),0) -> 10.394325 | E14: =IFERROR(NORMINV(RAND(),'Passangers Analysis'!E14,'Passangers Analysis'!E14*0.2),0) -> 6.2170833 | F14: =IFERROR(NORMINV(RAND(),'Passangers Analysis'!F14,'Passangers Analysis'!F14*0.2),0) -> 49.045135 | G14: =IFERROR(NORMINV(RAND(),'Passangers Analysis'!G14,'Passangers Analysis'!G14*0.2),0) -> 19.500285 | H14: =IFERROR(NORMINV(RAND(),'Passangers Analysis'!H14,'Passangers Analysis'!H14*0.2),0) -> 53.477549 | I14: =IFERROR(NORMINV(RAND(),'Passangers Analysis'!I14,'Passangers Analysis'!I14*0.2),0) -> 0 | J14: =IFERROR(NORMINV(RAND(),'Passangers Analysis'!J14,'Passangers Analysis'!J14*0.2),0) -> 50.078173 | ... W14: =IFERROR(NORMINV(RAND(),'Passangers Analysis'!W14,'Passangers Analysis'!W14*0.2),0) -> 22.626382 | X14: =SUMIFS(C14:W14,$C$5:$W$5,">"&A14) -> 672.98038 | Y14: =I29 -> 99.107457 | Z14: =Z13+X14-Y14 -> 4840.6074 | AA14: =Z14/Results!$C$13 -> 1210.1518 | AB14: =AA14/Results!$C$6 -> 23.728467 | AD14: =SUMIFS(C14:W14,$C$5:$W$5,"<"&A14) -> 159.0919 | AE14: =I30 -> 368.00406 | AF14: =AF15+AD14-AE14 -> 3223.0606 | AG14: =AF14/Results!$C$13 -> 805.76516 | AH14: =AG14/Results!$C$6 -> 15.799317
A15: 8 | B15: GPO | C15: =IFERROR(NORMINV(RAND(),'Passangers Analysis'!C15,'Passangers Analysis'!C15*0.2),0) -> 10.175276 | D15: =IFERROR(NORMINV(RAND(),'Passangers Analysis'!D15,'Passangers Analysis'!D15*0.2),0) -> 9.3343951 | E15: =IFERROR(NORMINV(RAND(),'Passangers Analysis'!E15,'Passangers Analysis'!E15*0.2),0) -> 5.583466 | F15: =IFERROR(NORMINV(RAND(),'Passangers Analysis'!F15,'Passangers Analysis'!F15*0.2),0) -> 123.49944 | G15: =IFERROR(NORMINV(RAND(),'Passangers Analysis'!G15,'Passangers Analysis'!G15*0.2),0) -> 26.064315 | H15: =IFERROR(NORMINV(RAND(),'Passangers Analysis'!H15,'Passangers Analysis'!H15*0.2),0) -> 57.748633 | I15: =IFERROR(NORMINV(RAND(),'Passangers Analysis'!I15,'Passangers Analysis'!I15*0.2),0) -> 10.587411 | J15: =IFERROR(NORMINV(RAND(),'Passangers Analysis'!J15,'Passangers Analysis'!J15*0.2),0) -> 0 | ... W15: =IFERROR(NORMINV(RAND(),'Passangers Analysis'!W15,'Passangers Analysis'!W15*0.2),0) -> 19.320409 | X15: =SUMIFS(C15:W15,$C$5:$W$5,">"&A15) -> 621.42969 | Y15: =J29 -> 526.1497 | Z15: =Z14+X15-Y15 -> 4935.8874 | AA15: =Z15/Results!$C$13 -> 1233.9718 | AB15: =AA15/Results!$C$6 -> 24.195526 | AD15: =SUMIFS(C15:W15,$C$5:$W$5,"<"&A15) -> 242.99294 | AE15: =J30 -> 963.8499 | AF15: =AF16+AD15-AE15 -> 3431.9728 | AG15: =AF15/Results!$C$13 -> 857.9932 | AH15: =AG15/Results!$C$6 -> 16.823396
A16: 9 | B16: Shivaji Vatika | C16: =IFERROR(NORMINV(RAND(),'Passangers Analysis'!C16,'Passangers Analysis'!C16*0.2),0) -> 3.7517034 | D16: =IFERROR(NORMINV(RAND(),'Passangers Analysis'!D16,'Passangers Analysis'!D16*0.2),0) -> 3.9285932 | E16: =IFERROR(NORMINV(RAND(),'Passangers Analysis'!E16,'Passangers Analysis'!E16*0.2),0) -> 3.1264479 | F16: =IFERROR(NORMINV(RAND(),'Passangers Analysis'!F16,'Passangers Analysis'!F16*0.2),0) -> 23.413927 | G16: =IFERROR(NORMINV(RAND(),'Passangers Analysis'!G16,'Passangers Analysis'!G16*0.2),0) -> 10.972225 | H16: =IFERROR(NORMINV(RAND(),'Passangers Analysis'!H16,'Passangers Analysis'!H16*0.2),0) -> 14.6074 | I16: =IFERROR(NORMINV(RAND(),'Passangers Analysis'!I16,'Passangers Analysis'!I16*0.2),0) -> 5.0203325 | J16: =IFERROR(NORMINV(RAND(),'Passangers Analysis'!J16,'Passangers Analysis'!J16*0.2),0) -> 33.641745 | ... W16: =IFERROR(NORMINV(RAND(),'Passangers Analysis'!W16,'Passangers Analysis'!W16*0.2),0) -> 6.9087906 | X16: =SUMIFS(C16:W16,$C$5:$W$5,">"&A16) -> 148.47957 | Y16: =K29 -> 159.95377 | Z16: =Z15+X16-Y16 -> 4924.4132 | AA16: =Z16/Results!$C$13 -> 1231.1033 | AB16: =AA16/Results!$C$6 -> 24.13928 | AD16: =SUMIFS(C16:W16,$C$5:$W$5,"<"&A16) -> 98.462374 | AE16: =K30 -> 278.36907 | AF16: =AF17+AD16-AE16 -> 4152.8298 | AG16: =AF16/Results!$C$13 -> 1038.2074 | AH16: =AG16/Results!$C$6 -> 20.357009
A17: 10 | B17: AICTSL | C17: =IFERROR(NORMINV(RAND(),'Passangers Analysis'!C17,'Passangers Analysis'!C17*0.2),0) -> 17.619748 | D17: =IFERROR(NORMINV(RAND(),'Passangers Analysis'!D17,'Passangers Analysis'!D17*0.2),0) -> 6.6158237 | E17: =IFERROR(NORMINV(RAND(),'Passangers Analysis'!E17,'Passangers Analysis'!E17*0.2),0) -> 3.1582456 | F17: =IFERROR(NORMINV(RAND(),'Passangers Analysis'!F17,'Passangers Analysis'!F17*0.2),0) -> 48.62006 | G17: =IFERROR(NORMINV(RAND(),'Passangers Analysis'!G17,'Passangers Analysis'!G17*0.2),0) -> 18.573699 | H17: =IFERROR(NORMINV(RAND(),'Passangers Analysis'!H17,'Passangers Analysis'!H17*0.2),0) -> 26.422222 | I17: =IFERROR(NORMINV(RAND(),'Passangers Analysis'!I17,'Passangers Analysis'!I17*0.2),0) -> 33.874686 | J17: =IFERROR(NORMINV(RAND(),'Passangers Analysis'!J17,'Passangers Analysis'!J17*0.2),0) -> 35.957959 | ... W17: =IFERROR(NORMINV(RAND(),'Passangers Analysis'!W17,'Passangers Analysis'!W17*0.2),0) -> 10.70975 | X17: =SUMIFS(C17:W17,$C$5:$W$5,">"&A17) -> 249.96414 | Y17: =L29 -> 293.47106 | Z17: =Z16+X17-Y17 -> 4880.9062 | AA17: =Z17/Results!$C$13 -> 1220.2266 | AB17: =AA17/Results!$C$6 -> 23.926011 | AD17: =SUMIFS(C17:W17,$C$5:$W$5,"<"&A17) -> 213.94769 | AE17: =L30 -> 363.90755 | AF17: =AF18+AD17-AE17 -> 4332.7365 | AG17: =AF17/Results!$C$13 -> 1083.1841 | AH17: =AG17/Results!$C$6 -> 21.238904
A18: 11 | B18: Geeta Bhawan | C18: =IFERROR(NORMINV(RAND(),'Passangers Analysis'!C18,'Passangers Analysis'!C18*0.2),0) -> 22.133663 | D18: =IFERROR(NORMINV(RAND(),'Passangers Analysis'!D18,'Passangers Analysis'!D18*0.2),0) -> 9.121239 | E18: =IFERROR(NORMINV(RAND(),'Passangers Analysis'!E18,'Passangers Analysis'!E18*0.2),0) -> 9.6824051 | F18: =IFERROR(NORMINV(RAND(),'Passangers Analysis'!F18,'Passangers Analysis'!F18*0.2),0) -> 251.89722 | G18: =IFERROR(NORMINV(RAND(),'Passangers Analysis'!G18,'Passangers Analysis'!G18*0.2),0) -> 40.667286 | H18: =IFERROR(NORMINV(RAND(),'Passangers Analysis'!H18,'Passangers Analysis'!H18*0.2),0) -> 56.861827 | I18: =IFERROR(NORMINV(RAND(),'Passangers Analysis'!I18,'Passangers Analysis'!I18*0.2),0) -> 29.630227 | J18: =IFERROR(NORMINV(RAND(),'Passangers Analysis'!J18,'Passangers Analysis'!J18*0.2),0) -> 97.725248 | ... W18: =IFERROR(NORMINV(RAND(),'Passangers Analysis'!W18,'Passangers Analysis'!W18*0.2),0) -> 23.602507 | X18: =SUMIFS(C18:W18,$C$5:$W$5,">"&A18) -> 793.86697 | Y18: =M29 -> 1030.7811 | Z18: =Z17+X18-Y18 -> 4643.9921 | AA18: =Z18/Results!$C$13 -> 1160.998 | AB18: =AA18/Results!$C$6 -> 22.764667 | AD18: =SUMIFS(C18:W18,$C$5:$W$5,"<"&A18) -> 632.08223 | AE18: =M30 -> 1369.8058 | AF18: =AF19+AD18-AE18 -> 4482.6963 | AG18: =AF18/Results!$C$13 -> 1120.6741 | AH18: =AG18/Results!$C$6 -> 21.974002
A19: 12 | B19: Palasiya | C19: =IFERROR(NORMINV(RAND(),'Passangers Analysis'!C19,'Passangers Analysis'!C19*0.2),0) -> 33.078962 | D19: =IFERROR(NORMINV(RAND(),'Passangers Analysis'!D19,'Passangers Analysis'!D19*0.2),0) -> 11.281559 | E19: =IFERROR(NORMINV(RAND(),'Passangers Analysis'!E19,'Passangers Analysis'!E19*0.2),0) -> 9.3269429 | F19: =IFERROR(NORMINV(RAND(),'Passangers Analysis'!F19,'Passangers Analysis'!F19*0.2),0) -> 234.45488 | G19: =IFERROR(NORMINV(RAND(),'Passangers Analysis'!G19,'Passangers Analysis'!G19*0.2),0) -> 27.618956 | H19: =IFERROR(NORMINV(RAND(),'Passangers Analysis'!H19,'Passangers Analysis'!H19*0.2),0) -> 100.78836 | I19: =IFERROR(NORMINV(RAND(),'Passangers Analysis'!I19,'Passangers Analysis'!I19*0.2),0) -> 25.778649 | J19: =IFERROR(NORMINV(RAND(),'Passangers Analysis'!J19,'Passangers Analysis'!J19*0.2),0) -> 165.52107 | ... W19: =IFERROR(NORMINV(RAND(),'Passangers Analysis'!W19,'Passangers Analysis'!W19*0.2),0) -> 24.890475 | X19: =SUMIFS(C19:W19,$C$5:$W$5,">"&A19) -> 471.57269 | Y19: =N29 -> 1339.476 | Z19: =Z18+X19-Y19 -> 3776.0888 | AA19: =Z19/Results!$C$13 -> 944.0222 | AB19: =AA19/Results!$C$6 -> 18.510239 | AD19: =SUMIFS(C19:W19,$C$5:$W$5,"<"&A19) -> 855.06306 | AE19: =N30 -> 922.23763 | AF19: =AF20+AD19-AE19 -> 5220.4199 | AG19: =AF19/Results!$C$13 -> 1305.105 | AH19: =AG19/Results!$C$6 -> 25.590294
A20: 13 | B20: Industry House | C20: =IFERROR(NORMINV(RAND(),'Passangers Analysis'!C20,'Passangers Analysis'!C20*0.2),0) -> 7.2537658 | D20: =IFERROR(NORMINV(RAND(),'Passangers Analysis'!D20,'Passangers Analysis'!D20*0.2),0) -> 5.2466483 | E20: =IFERROR(NORMINV(RAND(),'Passangers Analysis'!E20,'Passangers Analysis'!E20*0.2),0) -> 0 | F20: =IFERROR(NORMINV(RAND(),'Passangers Analysis'!F20,'Passangers Analysis'!F20*0.2),0) -> 46.996816 | G20: =IFERROR(NORMINV(RAND(),'Passangers Analysis'!G20,'Passangers Analysis'!G20*0.2),0) -> 14.758065 | H20: =IFERROR(NORMINV(RAND(),'Passangers Analysis'!H20,'Passangers Analysis'!H20*0.2),0) -> 15.916301 | I20: =IFERROR(NORMINV(RAND(),'Passangers Analysis'!I20,'Passangers Analysis'!I20*0.2),0) -> 10.198947 | J20: =IFERROR(NORMINV(RAND(),'Passangers Analysis'!J20,'Passangers Analysis'!J20*0.2),0) -> 34.851104 | ... W20: =IFERROR(NORMINV(RAND(),'Passangers Analysis'!W20,'Passangers Analysis'!W20*0.2),0) -> 12.894534 | X20: =SUMIFS(C20:W20,$C$5:$W$5,">"&A20) -> 115.2777 | Y20: =O29 -> 366.99713 | Z20: =Z19+X20-Y20 -> 3524.3694 | AA20: =Z20/Results!$C$13 -> 881.09234 | AB20: =AA20/Results!$C$6 -> 17.27632 | AD20: =SUMIFS(C20:W20,$C$5:$W$5,"<"&A20) -> 258.58948 | AE20: =O30 -> 269.53782 | AF20: =AF21+AD20-AE20 -> 5287.5945 | AG20: =AF20/Results!$C$13 -> 1321.8986 | AH20: =AG20/Results!$C$6 -> 25.919581
A21: 14 | B21: LIG | C21: =IFERROR(NORMINV(RAND(),'Passangers Analysis'!C21,'Passangers Analysis'!C21*0.2),0) -> 25.855891 | D21: =IFERROR(NORMINV(RAND(),'Passangers Analysis'!D21,'Passangers Analysis'!D21*0.2),0) -> 15.224433 | E21: =IFERROR(NORMINV(RAND(),'Passangers Analysis'!E21,'Passangers Analysis'!E21*0.2),0) -> 9.3074982 | F21: =IFERROR(NORMINV(RAND(),'Passangers Analysis'!F21,'Passangers Analysis'!F21*0.2),0) -> 116.36517 | G21: =IFERROR(NORMINV(RAND(),'Passangers Analysis'!G21,'Passangers Analysis'!G21*0.2),0) -> 18.535755 | H21: =IFERROR(NORMINV(RAND(),'Passangers Analysis'!H21,'Passangers Analysis'!H21*0.2),0) -> 54.859977 | I21: =IFERROR(NORMINV(RAND(),'Passangers Analysis'!I21,'Passangers Analysis'!I21*0.2),0) -> 20.514886 | J21: =IFERROR(NORMINV(RAND(),'Passangers Analysis'!J21,'Passangers Analysis'!J21*0.2),0) -> 74.567986 | ... W21: =IFERROR(NORMINV(RAND(),'Passangers Analysis'!W21,'Passangers Analysis'!W21*0.2),0) -> 13.180359 | X21: =SUMIFS(C21:W21,$C$5:$W$5,">"&A21) -> 243.24924 | Y21: =P29 -> 1250.1334 | Z21: =Z20+X21-Y21 -> 2517.4852 | AA21: =Z21/Results!$C$13 -> 629.37129 | AB21: =AA21/Results!$C$6 -> 12.340614 | AD21: =SUMIFS(C21:W21,$C$5:$W$5,"<"&A21) -> 886.54679 | AE21: =P30 -> 700.78554 | AF21: =AF22+AD21-AE21 -> 5298.5428 | AG21: =AF21/Results!$C$13 -> 1324.6357 | AH21: =AG21/Results!$C$6 -> 25.973249
A22: 15 | B22: Press Complex | C22: =IFERROR(NORMINV(RAND(),'Passangers Analysis'!C22,'Passangers Analysis'!C22*0.2),0) -> 12.958115 | D22: =IFERROR(NORMINV(RAND(),'Passangers Analysis'!D22,'Passangers Analysis'!D22*0.2),0) -> 5.381111 | E22: =IFERROR(NORMINV(RAND(),'Passangers Analysis'!E22,'Passangers Analysis'!E22*0.2),0) -> 5.8431132 | F22: =IFERROR(NORMINV(RAND(),'Passangers Analysis'!F22,'Passangers Analysis'!F22*0.2),0) -> 43.208506 | G22: =IFERROR(NORMINV(RAND(),'Passangers Analysis'!G22,'Passangers Analysis'!G22*0.2),0) -> 23.419067 | H22: =IFERROR(NORMINV(RAND(),'Passangers Analysis'!H22,'Passangers Analysis'!H22*0.2),0) -> 27.095556 | I22: =IFERROR(NORMINV(RAND(),'Passangers Analysis'!I22,'Passangers Analysis'!I22*0.2),0) -> 24.408058 | J22: =IFERROR(NORMINV(RAND(),'Passangers Analysis'!J22,'Passangers Analysis'!J22*0.2),0) -> 27.877992 | ... W22: =IFERROR(NORMINV(RAND(),'Passangers Analysis'!W22,'Passangers Analysis'!W22*0.2),0) -> 9.4626364 | X22: =SUMIFS(C22:W22,$C$5:$W$5,">"&A22) -> 95.699842 | Y22: =Q29 -> 181.07297 | Z22: =Z21+X22-Y22 -> 2432.112 | AA22: =Z22/Results!$C$13 -> 608.02801 | AB22: =AA22/Results!$C$6 -> 11.922118 | AD22: =SUMIFS(C22:W22,$C$5:$W$5,"<"&A22) -> 382.67956 | AE22: =Q30 -> 82.083128 | AF22: =AF23+AD22-AE22 -> 5112.7816 | AG22: =AF22/Results!$C$13 -> 1278.1954 | AH22: =AG22/Results!$C$6 -> 25.062655
A23: 16 | B23: MR-9 | C23: =IFERROR(NORMINV(RAND(),'Passangers Analysis'!C23,'Passangers Analysis'!C23*0.2),0) -> 14.187257 | D23: =IFERROR(NORMINV(RAND(),'Passangers Analysis'!D23,'Passangers Analysis'!D23*0.2),0) -> 15.64536 | E23: =IFERROR(NORMINV(RAND(),'Passangers Analysis'!E23,'Passangers Analysis'!E23*0.2),0) -> 12.292402 | F23: =IFERROR(NORMINV(RAND(),'Passangers Analysis'!F23,'Passangers Analysis'!F23*0.2),0) -> 141.19105 | G23: =IFERROR(NORMINV(RAND(),'Passangers Analysis'!G23,'Passangers Analysis'!G23*0.2),0) -> 59.985558 | H23: =IFERROR(NORMINV(RAND(),'Passangers Analysis'!H23,'Passangers Analysis'!H23*0.2),0) -> 219.19731 | I23: =IFERROR(NORMINV(RAND(),'Passangers Analysis'!I23,'Passangers Analysis'!I23*0.2),0) -> 73.042667 | J23: =IFERROR(NORMINV(RAND(),'Passangers Analysis'!J23,'Passangers Analysis'!J23*0.2),0) -> 102.65234 | ... W23: =IFERROR(NORMINV(RAND(),'Passangers Analysis'!W23,'Passangers Analysis'!W23*0.2),0) -> 44.697655 | X23: =SUMIFS(C23:W23,$C$5:$W$5,">"&A23) -> 221.43764 | Y23: =R29 -> 999.96581 | Z23: =Z22+X23-Y23 -> 1653.5839 | AA23: =Z23/Results!$C$13 -> 413.39597 | AB23: =AA23/Results!$C$6 -> 8.1058032 | AD23: =SUMIFS(C23:W23,$C$5:$W$5,"<"&A23) -> 1642.5593 | AE23: =R30 -> 292.04628 | AF23: =AF24+AD23-AE23 -> 4812.1851 | AG23: =AF23/Results!$C$13 -> 1203.0463 | AH23: =AG23/Results!$C$6 -> 23.589143
A24: 17 | B24: Vijay Nagar | C24: =IFERROR(NORMINV(RAND(),'Passangers Analysis'!C24,'Passangers Analysis'!C24*0.2),0) -> 34.001787 | D24: =IFERROR(NORMINV(RAND(),'Passangers Analysis'!D24,'Passangers Analysis'!D24*0.2),0) -> 23.269918 | E24: =IFERROR(NORMINV(RAND(),'Passangers Analysis'!E24,'Passangers Analysis'!E24*0.2),0) -> 13.820318 | F24: =IFERROR(NORMINV(RAND(),'Passangers Analysis'!F24,'Passangers Analysis'!F24*0.2),0) -> 176.22707 | G24: =IFERROR(NORMINV(RAND(),'Passangers Analysis'!G24,'Passangers Analysis'!G24*0.2),0) -> 35.885443 | H24: =IFERROR(NORMINV(RAND(),'Passangers Analysis'!H24,'Passangers Analysis'!H24*0.2),0) -> 99.083574 | I24: =IFERROR(NORMINV(RAND(),'Passangers Analysis'!I24,'Passangers Analysis'!I24*0.2),0) -> 63.627326 | J24: =IFERROR(NORMINV(RAND(),'Passangers Analysis'!J24,'Passangers Analysis'!J24*0.2),0) -> 240.07989 | ... W24: =IFERROR(NORMINV(RAND(),'Passangers Analysis'!W24,'Passangers Analysis'!W24*0.2),0) -> 41.193128 | X24: =SUMIFS(C24:W24,$C$5:$W$5,">"&A24) -> 140.75697 | Y24: =S29 -> 713.03846 | Z24: =Z23+X24-Y24 -> 1081.3024 | AA24: =Z24/Results!$C$13 -> 270.32559 | AB24: =AA24/Results!$C$6 -> 5.3005018 | AD24: =SUMIFS(C24:W24,$C$5:$W$5,"<"&A24) -> 1698.6877 | AE24: =S30 -> 127.84463 | AF24: =AF25+AD24-AE24 -> 3461.6721 | AG24: =AF24/Results!$C$13 -> 865.41803 | AH24: =AG24/Results!$C$6 -> 16.968981
A25: 18 | B25: Satya Sai | C25: =IFERROR(NORMINV(RAND(),'Passangers Analysis'!C25,'Passangers Analysis'!C25*0.2),0) -> 5.2490315 | D25: =IFERROR(NORMINV(RAND(),'Passangers Analysis'!D25,'Passangers Analysis'!D25*0.2),0) -> 7.3091169 | E25: =IFERROR(NORMINV(RAND(),'Passangers Analysis'!E25,'Passangers Analysis'!E25*0.2),0) -> 10.823116 | F25: =IFERROR(NORMINV(RAND(),'Passangers Analysis'!F25,'Passangers Analysis'!F25*0.2),0) -> 34.375025 | G25: =IFERROR(NORMINV(RAND(),'Passangers Analysis'!G25,'Passangers Analysis'!G25*0.2),0) -> 14.048161 | H25: =IFERROR(NORMINV(RAND(),'Passangers Analysis'!H25,'Passangers Analysis'!H25*0.2),0) -> 19.403598 | I25: =IFERROR(NORMINV(RAND(),'Passangers Analysis'!I25,'Passangers Analysis'!I25*0.2),0) -> 17.483389 | J25: =IFERROR(NORMINV(RAND(),'Passangers Analysis'!J25,'Passangers Analysis'!J25*0.2),0) -> 20.509239 | ... W25: =IFERROR(NORMINV(RAND(),'Passangers Analysis'!W25,'Passangers Analysis'!W25*0.2),0) -> 9.5931444 | X25: =SUMIFS(C25:W25,$C$5:$W$5,">"&A25) -> 29.696596 | Y25: =T29 -> 192.34061 | Z25: =Z24+X25-Y25 -> 918.65835 | AA25: =Z25/Results!$C$13 -> 229.66459 | AB25: =AA25/Results!$C$6 -> 4.5032272 | AD25: =SUMIFS(C25:W25,$C$5:$W$5,"<"&A25) -> 299.98066 | AE25: =T30 -> 22.854299 | AF25: =AF26+AD25-AE25 -> 1890.8291 | AG25: =AF25/Results!$C$13 -> 472.70726 | AH25: =AG25/Results!$C$6 -> 9.2687699
A26: 19 | B26: Shalimar Township | C26: =IFERROR(NORMINV(RAND(),'Passangers Analysis'!C26,'Passangers Analysis'!C26*0.2),0) -> 10.391032 | D26: =IFERROR(NORMINV(RAND(),'Passangers Analysis'!D26,'Passangers Analysis'!D26*0.2),0) -> 8.8974838 | E26: =IFERROR(NORMINV(RAND(),'Passangers Analysis'!E26,'Passangers Analysis'!E26*0.2),0) -> 5.0870732 | F26: =IFERROR(NORMINV(RAND(),'Passangers Analysis'!F26,'Passangers Analysis'!F26*0.2),0) -> 34.897015 | G26: =IFERROR(NORMINV(RAND(),'Passangers Analysis'!G26,'Passangers Analysis'!G26*0.2),0) -> 23.493392 | H26: =IFERROR(NORMINV(RAND(),'Passangers Analysis'!H26,'Passangers Analysis'!H26*0.2),0) -> 15.494357 | I26: =IFERROR(NORMINV(RAND(),'Passangers Analysis'!I26,'Passangers Analysis'!I26*0.2),0) -> 11.309516 | J26: =IFERROR(NORMINV(RAND(),'Passangers Analysis'!J26,'Passangers Analysis'!J26*0.2),0) -> 45.331523 | ... W26: =IFERROR(NORMINV(RAND(),'Passangers Analysis'!W26,'Passangers Analysis'!W26*0.2),0) -> 15.814806 | X26: =SUMIFS(C26:W26,$C$5:$W$5,">"&A26) -> 23.388639 | Y26: =U29 -> 220.81296 | Z26: =Z25+X26-Y26 -> 721.23404 | AA26: =Z26/Results!$C$13 -> 180.30851 | AB26: =AA26/Results!$C$6 -> 3.535461 | AD26: =SUMIFS(C26:W26,$C$5:$W$5,"<"&A26) -> 378.82428 | AE26: =U30 -> 23.472809 | AF26: =AF27+AD26-AE26 -> 1613.7027 | AG26: =AF26/Results!$C$13 -> 403.42567 | AH26: =AG26/Results!$C$6 -> 7.9103073
A27: 20 | B27: Scheme No. 78 | C27: =IFERROR(NORMINV(RAND(),'Passangers Analysis'!C27,'Passangers Analysis'!C27*0.2),0) -> 30.638217 | D27: =IFERROR(NORMINV(RAND(),'Passangers Analysis'!D27,'Passangers Analysis'!D27*0.2),0) -> 10.937726 | E27: =IFERROR(NORMINV(RAND(),'Passangers Analysis'!E27,'Passangers Analysis'!E27*0.2),0) -> 7.4595837 | F27: =IFERROR(NORMINV(RAND(),'Passangers Analysis'!F27,'Passangers Analysis'!F27*0.2),0) -> 77.805428 | G27: =IFERROR(NORMINV(RAND(),'Passangers Analysis'!G27,'Passangers Analysis'!G27*0.2),0) -> 22.157106 | H27: =IFERROR(NORMINV(RAND(),'Passangers Analysis'!H27,'Passangers Analysis'!H27*0.2),0) -> 35.984637 | I27: =IFERROR(NORMINV(RAND(),'Passangers Analysis'!I27,'Passangers Analysis'!I27*0.2),0) -> 13.705116 | J27: =IFERROR(NORMINV(RAND(),'Passangers Analysis'!J27,'Passangers Analysis'!J27*0.2),0) -> 38.522871 | ... W27: =IFERROR(NORMINV(RAND(),'Passangers Analysis'!W27,'Passangers Analysis'!W27*0.2),0) -> 15.444242 | X27: =SUMIFS(C27:W27,$C$5:$W$5,">"&A27) -> 15.444242 | Y27: =V29 -> 354.05662 | Z27: =Z26+X27-Y27 -> 382.62166 | AA27: =Z27/Results!$C$13 -> 95.655415 | AB27: =AA27/Results!$C$6 -> 1.8755964 | AD27: =SUMIFS(C27:W27,$C$5:$W$5,"<"&A27) -> 605.03833 | AE27: =V30 -> 28.228 | AF27: =AF28+AD27-AE27 -> 1258.3512 | AG27: =AF27/Results!$C$13 -> 314.58781 | AH27: =AG27/Results!$C$6 -> 6.1683883
A28: 21 | B28: Niranjanpur Square | C28: =IFERROR(NORMINV(RAND(),'Passangers Analysis'!C28,'Passangers Analysis'!C28*0.2),0) -> 18.145026 | D28: =IFERROR(NORMINV(RAND(),'Passangers Analysis'!D28,'Passangers Analysis'!D28*0.2),0) -> 7.2502808 | E28: =IFERROR(NORMINV(RAND(),'Passangers Analysis'!E28,'Passangers Analysis'!E28*0.2),0) -> 8.6389707 | F28: =IFERROR(NORMINV(RAND(),'Passangers Analysis'!F28,'Passangers Analysis'!F28*0.2),0) -> 86.67959 | G28: =IFERROR(NORMINV(RAND(),'Passangers Analysis'!G28,'Passangers Analysis'!G28*0.2),0) -> 24.63819 | H28: =IFERROR(NORMINV(RAND(),'Passangers Analysis'!H28,'Passangers Analysis'!H28*0.2),0) -> 31.023823 | I28: =IFERROR(NORMINV(RAND(),'Passangers Analysis'!I28,'Passangers Analysis'!I28*0.2),0) -> 28.822852 | J28: =IFERROR(NORMINV(RAND(),'Passangers Analysis'!J28,'Passangers Analysis'!J28*0.2),0) -> 46.610932 | ... W28: =IFERROR(NORMINV(RAND(),'Passangers Analysis'!W28,'Passangers Analysis'!W28*0.2),0) -> 0 | X28: =SUMIFS(C28:W28,$C$5:$W$5,">"&A28) -> 0 | Y28: =W29 -> 382.62166 | Z28: =Z27+X28-Y28 -> 0 | AA28: =Z28/Results!$C$13 -> 0 | AB28: =AA28/Results!$C$6 -> 0 | AD28: =SUMIFS(C28:W28,$C$5:$W$5,"<"&A28) -> 681.54089 | AE28: =W30 -> 0 | AF28: =AD28-AE28 -> 681.54089 | AG28: =AF28/Results!$C$13 -> 170.38522 | AH28: =AG28/Results!$C$6 -> 3.3408867
B29: Northbound unloading | C29: {=SUM(IF($A$8:$A$28<C$5,C8:C28,0))} -> 0 | D29: {=SUM(IF($A$8:$A$28<D$5,D8:D28,0))} -> 6.5922689 | E29: {=SUM(IF($A$8:$A$28<E$5,E8:E28,0))} -> 8.6689934 | F29: {=SUM(IF($A$8:$A$28<F$5,F8:F28,0))} -> 132.83273 | G29: {=SUM(IF($A$8:$A$28<G$5,G8:G28,0))} -> 54.419291 | H29: {=SUM(IF($A$8:$A$28<H$5,H8:H28,0))} -> 112.24582 | I29: {=SUM(IF($A$8:$A$28<I$5,I8:I28,0))} -> 99.107457 | J29: {=SUM(IF($A$8:$A$28<J$5,J8:J28,0))} -> 526.1497 | ... W29: {=SUM(IF($A$8:$A$28<W$5,W8:W28,0))} -> 382.62166 | AA29: Required | AB29: =ROUNDUP(MAX(AB8:AB28),0) -> 25 | AG29: Required | AH29: =ROUNDUP(MAX(AH8:AH28),0) -> 26
B30: Southbound unloading | C30: {=SUM(IF($A$8:$A$28>C$5,C8:C28,0))} -> 340.1262 | D30: {=SUM(IF($A$8:$A$28>D$5,D8:D28,0))} -> 196.03025 | E30: {=SUM(IF($A$8:$A$28>E$5,E8:E28,0))} -> 137.63534 | F30: {=SUM(IF($A$8:$A$28>F$5,F8:F28,0))} -> 1714.5743 | G30: {=SUM(IF($A$8:$A$28>G$5,G8:G28,0))} -> 423.42279 | H30: {=SUM(IF($A$8:$A$28>H$5,H8:H28,0))} -> 827.96513 | I30: {=SUM(IF($A$8:$A$28>I$5,I8:I28,0))} -> 368.00406 | J30: {=SUM(IF($A$8:$A$28>J$5,J8:J28,0))} -> 963.8499 | ... W30: {=SUM(IF($A$8:$A$28>W$5,W8:W28,0))} -> 0 | AA30: Demand met | AB30: =IF(Results!C7-'Normal Distribution simulation'!AB29>=0,1,0) -> 1 | AG30: Demand met | AH30: =IF(Results!C7-'Normal Distribution simulation'!AH29>=0,1,0) -> 1
A35: Note: *distance is measured from the origin (Rajiv Gandhi) to the specified stop; the number of passengers is the total number of passengers travelling between an origin
A36: (row) and destination (column) over the measured period; km = kilometres; AICTSL = Atal Indore City Transport Service Limited
A37: Source: Company files.
A39: Page 8 | B39: EXHIBIT 6: ORIGIN-DESTINATION DEMAND MATRIX FOR NON-PEAK HOURS (11:30 A.M. TO 14:30 P.M.) IN NUMBER OF PASSENGERS
B41: Bus Stop Number | C41: 1 | D41: 2 | E41: 3 | F41: 4 | G41: 5 | H41: 6 | I41: 7 | J41: 8 | K41: 9 | L41: 10 | M41: 11 | N41: 12 | O41: 13 | P41: 14 | Q41: 15 | R41: 16 | S41: 17 | T41: 18 | U41: 19 | V41: 20 | W41: 21
B42: Bus Stop Name | C42: Rajiv Gandhi | D42: Mata Gujri | E42: Vishnupuri | F42: Bhanwarkuan Square | G42: Holkar Subway | H42: Navlakha Square | I42: Indra Pratima | J42: GPO | K42: Shivaji Vatika | L42: AICTSL | M42: Geeta Bhawan | N42: Palasiya | O42: Industry House | P42: LIG | Q42: Press Complex | R42: MR-9 | S42: Vijay Nagar | T42: Satya Sai | U42: Shalimar Township | V42: Scheme No. 78 | W42: Niranjanpur Square
B43: Distance* (in km) | C43: 0 | D43: 0.75 | E43: 1.2 | F43: 1.7 | G43: 2 | H43: 3 | I43: 3.3 | J43: 3.7 | K43: 4.4 | L43: 4.9 | M43: 5.4 | N43: 6.1 | O43: 6.6 | P43: 7.2 | Q43: 7.5 | R43: 8.2 | S43: 8.9 | T43: 9.5 | U43: 10.4 | V43: 10.9 | W43: 11.4 | X43: Northbound Loading | Y43: Northbound Unloading | Z43: Northbound Total people (raw) | AA43: Northbound Per hour | AB43: Buses per hour | AD43: Southbound loading | AE43: Southbound unloading | AF43: Southmound total | AG43: Southboound per hour | AH43: Buses per hour
A44: 1 | B44: Rajiv Gandhi | C44: =IFERROR(NORMINV(RAND(),'Passangers Analysis'!C40,'Passangers Analysis'!C40*0.2),0) -> 0 | D44: =IFERROR(NORMINV(RAND(),'Passangers Analysis'!D40,'Passangers Analysis'!D40*0.2),0) -> 2.7917323 | E44: =IFERROR(NORMINV(RAND(),'Passangers Analysis'!E40,'Passangers Analysis'!E40*0.2),0) -> 0.93808796 | F44: =IFERROR(NORMINV(RAND(),'Passangers Analysis'!F40,'Passangers Analysis'!F40*0.2),0) -> 10.397856 | G44: =IFERROR(NORMINV(RAND(),'Passangers Analysis'!G40,'Passangers Analysis'!G40*0.2),0) -> 3.4385058 | H44: =IFERROR(NORMINV(RAND(),'Passangers Analysis'!H40,'Passangers Analysis'!H40*0.2),0) -> 7.6871879 | I44: =IFERROR(NORMINV(RAND(),'Passangers Analysis'!I40,'Passangers Analysis'!I40*0.2),0) -> 4.5611897 | J44: =IFERROR(NORMINV(RAND(),'Passangers Analysis'!J40,'Passangers Analysis'!J40*0.2),0) -> 5.8588197 | ... W44: =IFERROR(NORMINV(RAND(),'Passangers Analysis'!W40,'Passangers Analysis'!W40*0.2),0) -> 4.1281914 | X44: =SUMIFS(C44:W44,$C$41:$W$41,">"&A44) -> 118.2724 | Y44: =C65 -> 0 | Z44: =X44-Y44 -> 118.2724 | AA44: =Z44/Results!$C$14 -> 39.424135 | AB44: =AA44/Results!$C$6 -> 0.77302225 | AD44: =SUMIFS(C44:W44,$C$41:$W$41,"<"&A44) -> 0 | AE44: =C66 -> 127.59663 | AF44: =AF45+AD44-AE44 -> 0 | AG44: =AF44/Results!$C$14 -> 0 | AH44: =AG44/Results!$C$6 -> 0
A45: 2 | B45: Mata Gujri | C45: =IFERROR(NORMINV(RAND(),'Passangers Analysis'!C41,'Passangers Analysis'!C41*0.2),0) -> 1.8028028 | D45: =IFERROR(NORMINV(RAND(),'Passangers Analysis'!D41,'Passangers Analysis'!D41*0.2),0) -> 0 | E45: =IFERROR(NORMINV(RAND(),'Passangers Analysis'!E41,'Passangers Analysis'!E41*0.2),0) -> 2.4621727 | F45: =IFERROR(NORMINV(RAND(),'Passangers Analysis'!F41,'Passangers Analysis'!F41*0.2),0) -> 3.8464718 | G45: =IFERROR(NORMINV(RAND(),'Passangers Analysis'!G41,'Passangers Analysis'!G41*0.2),0) -> 1.153701 | H45: =IFERROR(NORMINV(RAND(),'Passangers Analysis'!H41,'Passangers Analysis'!H41*0.2),0) -> 7.4253113 | I45: =IFERROR(NORMINV(RAND(),'Passangers Analysis'!I41,'Passangers Analysis'!I41*0.2),0) -> 3.5436324 | J45: =IFERROR(NORMINV(RAND(),'Passangers Analysis'!J41,'Passangers Analysis'!J41*0.2),0) -> 5.9510831 | ... W45: =IFERROR(NORMINV(RAND(),'Passangers Analysis'!W41,'Passangers Analysis'!W41*0.2),0) -> 2.2551043 | X45: =SUMIFS(C45:W45,$C$41:$W$41,">"&A45) -> 72.540535 | Y45: =D65 -> 2.7917323 | Z45: =Z44+X45-Y45 -> 188.02121 | AA45: =Z45/Results!$C$14 -> 62.673735 | AB45: =AA45/Results!$C$6 -> 1.2288968 | AD45: =SUMIFS(C45:W45,$C$41:$W$41,"<"&A45) -> 1.8028028 | AE45: =D66 -> 63.357271 | AF45: =AF46+AD45-AE45 -> 127.59663 | AG45: =AF45/Results!$C$14 -> 42.53221 | AH45: =AG45/Results!$C$6 -> 0.83396489
A46: 3 | B46: Vishnupuri | C46: =IFERROR(NORMINV(RAND(),'Passangers Analysis'!C42,'Passangers Analysis'!C42*0.2),0) -> 2.1378381 | D46: =IFERROR(NORMINV(RAND(),'Passangers Analysis'!D42,'Passangers Analysis'!D42*0.2),0) -> 1.2581727 | E46: =IFERROR(NORMINV(RAND(),'Passangers Analysis'!E42,'Passangers Analysis'!E42*0.2),0) -> 0 | F46: =IFERROR(NORMINV(RAND(),'Passangers Analysis'!F42,'Passangers Analysis'!F42*0.2),0) -> 6.6516118 | G46: =IFERROR(NORMINV(RAND(),'Passangers Analysis'!G42,'Passangers Analysis'!G42*0.2),0) -> 1.8789642 | H46: =IFERROR(NORMINV(RAND(),'Passangers Analysis'!H42,'Passangers Analysis'!H42*0.2),0) -> 2.4377507 | I46: =IFERROR(NORMINV(RAND(),'Passangers Analysis'!I42,'Passangers Analysis'!I42*0.2),0) -> 2.5150624 | J46: =IFERROR(NORMINV(RAND(),'Passangers Analysis'!J42,'Passangers Analysis'!J42*0.2),0) -> 3.648361 | ... W46: =IFERROR(NORMINV(RAND(),'Passangers Analysis'!W42,'Passangers Analysis'!W42*0.2),0) -> 1.2132648 | X46: =SUMIFS(C46:W46,$C$41:$W$41,">"&A46) -> 52.161945 | Y46: =E65 -> 3.4002607 | Z46: =Z45+X46-Y46 -> 236.78289 | AA46: =Z46/Results!$C$14 -> 78.92763 | AB46: =AA46/Results!$C$6 -> 1.5476006 | AD46: =SUMIFS(C46:W46,$C$41:$W$41,"<"&A46) -> 3.3960108 | AE46: =E66 -> 50.14437 | AF46: =AF47+AD46-AE46 -> 189.1511 | AG46: =AF46/Results!$C$14 -> 63.050366 | AH46: =AG46/Results!$C$6 -> 1.2362817
A47: 4 | B47: Bhanwarkuan Square | C47: =IFERROR(NORMINV(RAND(),'Passangers Analysis'!C43,'Passangers Analysis'!C43*0.2),0) -> 7.8528782 | D47: =IFERROR(NORMINV(RAND(),'Passangers Analysis'!D43,'Passangers Analysis'!D43*0.2),0) -> 6.4448485 | E47: =IFERROR(NORMINV(RAND(),'Passangers Analysis'!E43,'Passangers Analysis'!E43*0.2),0) -> 5.1788566 | F47: =IFERROR(NORMINV(RAND(),'Passangers Analysis'!F43,'Passangers Analysis'!F43*0.2),0) -> 0 | G47: =IFERROR(NORMINV(RAND(),'Passangers Analysis'!G43,'Passangers Analysis'!G43*0.2),0) -> 5.9541755 | H47: =IFERROR(NORMINV(RAND(),'Passangers Analysis'!H43,'Passangers Analysis'!H43*0.2),0) -> 29.143986 | I47: =IFERROR(NORMINV(RAND(),'Passangers Analysis'!I43,'Passangers Analysis'!I43*0.2),0) -> 11.191046 | J47: =IFERROR(NORMINV(RAND(),'Passangers Analysis'!J43,'Passangers Analysis'!J43*0.2),0) -> 36.86823 | ... W47: =IFERROR(NORMINV(RAND(),'Passangers Analysis'!W43,'Passangers Analysis'!W43*0.2),0) -> 11.709718 | X47: =SUMIFS(C47:W47,$C$41:$W$41,">"&A47) -> 383.52353 | Y47: =F65 -> 20.89594 | Z47: =Z46+X47-Y47 -> 599.41048 | AA47: =Z47/Results!$C$14 -> 199.80349 | AB47: =AA47/Results!$C$6 -> 3.9177155 | AD47: =SUMIFS(C47:W47,$C$41:$W$41,"<"&A47) -> 19.476583 | AE47: =F66 -> 466.00088 | AF47: =AF48+AD47-AE47 -> 235.89946 | AG47: =AF47/Results!$C$14 -> 78.633152 | AH47: =AG47/Results!$C$6 -> 1.5418265
A48: 5 | B48: Holkar Subway | C48: =IFERROR(NORMINV(RAND(),'Passangers Analysis'!C44,'Passangers Analysis'!C44*0.2),0) -> 1.9019622 | D48: =IFERROR(NORMINV(RAND(),'Passangers Analysis'!D44,'Passangers Analysis'!D44*0.2),0) -> 1.7560466 | E48: =IFERROR(NORMINV(RAND(),'Passangers Analysis'!E44,'Passangers Analysis'!E44*0.2),0) -> 1.7364694 | F48: =IFERROR(NORMINV(RAND(),'Passangers Analysis'!F44,'Passangers Analysis'!F44*0.2),0) -> 7.2197073 | G48: =IFERROR(NORMINV(RAND(),'Passangers Analysis'!G44,'Passangers Analysis'!G44*0.2),0) -> 0 | H48: =IFERROR(NORMINV(RAND(),'Passangers Analysis'!H44,'Passangers Analysis'!H44*0.2),0) -> 4.1945105 | I48: =IFERROR(NORMINV(RAND(),'Passangers Analysis'!I44,'Passangers Analysis'!I44*0.2),0) -> 3.6909696 | J48: =IFERROR(NORMINV(RAND(),'Passangers Analysis'!J44,'Passangers Analysis'!J44*0.2),0) -> 7.438567 | ... W48: =IFERROR(NORMINV(RAND(),'Passangers Analysis'!W44,'Passangers Analysis'!W44*0.2),0) -> 3.9198765 | X48: =SUMIFS(C48:W48,$C$41:$W$41,">"&A48) -> 67.940186 | Y48: =G65 -> 12.425347 | Z48: =Z47+X48-Y48 -> 654.92532 | AA48: =Z48/Results!$C$14 -> 218.30844 | AB48: =AA48/Results!$C$6 -> 4.2805576 | AD48: =SUMIFS(C48:W48,$C$41:$W$41,"<"&A48) -> 12.614185 | AE48: =G66 -> 66.341232 | AF48: =AF49+AD48-AE48 -> 682.42376 | AG48: =AF48/Results!$C$14 -> 227.47459 | AH48: =AG48/Results!$C$6 -> 4.460286
A49: 6 | B49: Navlakha Square | C49: =IFERROR(NORMINV(RAND(),'Passangers Analysis'!C45,'Passangers Analysis'!C45*0.2),0) -> 11.616742 | D49: =IFERROR(NORMINV(RAND(),'Passangers Analysis'!D45,'Passangers Analysis'!D45*0.2),0) -> 4.9175867 | E49: =IFERROR(NORMINV(RAND(),'Passangers Analysis'!E45,'Passangers Analysis'!E45*0.2),0) -> 3.226932 | F49: =IFERROR(NORMINV(RAND(),'Passangers Analysis'!F45,'Passangers Analysis'!F45*0.2),0) -> 46.798927 | G49: =IFERROR(NORMINV(RAND(),'Passangers Analysis'!G45,'Passangers Analysis'!G45*0.2),0) -> 7.7435547 | H49: =IFERROR(NORMINV(RAND(),'Passangers Analysis'!H45,'Passangers Analysis'!H45*0.2),0) -> 0 | I49: =IFERROR(NORMINV(RAND(),'Passangers Analysis'!I45,'Passangers Analysis'!I45*0.2),0) -> 19.689646 | J49: =IFERROR(NORMINV(RAND(),'Passangers Analysis'!J45,'Passangers Analysis'!J45*0.2),0) -> 28.787894 | ... W49: =IFERROR(NORMINV(RAND(),'Passangers Analysis'!W45,'Passangers Analysis'!W45*0.2),0) -> 4.6410526 | X49: =SUMIFS(C49:W49,$C$41:$W$41,">"&A49) -> 306.83178 | Y49: =H65 -> 50.888747 | Z49: =Z48+X49-Y49 -> 910.86835 | AA49: =Z49/Results!$C$14 -> 303.62278 | AB49: =AA49/Results!$C$6 -> 5.9533879 | AD49: =SUMIFS(C49:W49,$C$41:$W$41,"<"&A49) -> 74.303742 | AE49: =H66 -> 346.92643 | AF49: =AF50+AD49-AE49 -> 736.1508 | AG49: =AF49/Results!$C$14 -> 245.3836 | AH49: =AG49/Results!$C$6 -> 4.8114432
...

Sheet Information
A1: Assumptions - Information
A3: Background info
A4: GDP Growth rate | B4: 50.24
A5: Rural areas population | B5: 68.80%
A6: urban population by 2050 | B6: 0.58 | C6: 875000000
A7: Registered buses 2016 | B7: 1750000
A8: public sector operated | B8: 170000
A9: transported people | B9: 70000000
A10: Bus used urban household | B10: 0.62 | C10: Auto rickshaw urban | D10: 0.47
A11: Bus spending rural household | B11: 0.66 | C11: Auto rickshaw rural | D11: 0.38
A14: The corridor was 11.57 kilometres long, with 21 bus stops
A15: The BRT buses travelled one route, in two directions: from Niranjanpur to Rajiv Gandhi and in the opposite direction from Rajiv Gandhi to Niranjanpur
A31: Route Length | B31: 11.57 | C31: kilometres
A32: Road Section (Road Width) | B32: 30-60 | C32: meters
A33: stops | B33: 21
A34: busies in the system | B34: 46
A35: bus capacity | B35: 36 | C35: seating | D35: 15 | E35: standing
A36: rideship | B36: over | C36: 52000 | D36: passengers per day

Sheet Results
B2: Weekly maximum KM: | C2: 1200
B3: Route legth: | C3: 11.4
B4: Roundtrip: | C4: =C3*2 -> 22.8
B5: Maximum roundtrips per week: | C5: =C2/C4 -> 52.631579
B6: Total bus capacity: | C6: 51
B7: Max buses Rush: | C7: 28 | E7: In one hour the bus can do a full one direction route, in two hours a roundtrip.
B8: Max Buses non rush: | C8: 9
B11: Passager demand per station forward direction (peak):
B13: Total Hours Peak | C13: 4
B14: Total Hours non-peak | C14: 3
B16: Station number | C16: Name
B17: Rajiv Gandhi | C17: 1
B18: Mata Gujri | C18: 2
B19: Vishnupuri | C19: 3
B20: Bhanwarkuan Square | C20: 4
B21: Holkar Subway | C21: 5
B22: Navlakha Square | C22: 6
B23: Indra Pratima | C23: 7
B24: GPO | C24: 8
B25: Shivaji Vatika | C25: 9
B26: AICTSL | C26: 10
B27: Geeta Bhawan | C27: 11
B28: Palasiya | C28: 12
... B37: Niranjanpur Square | C37: 21

Sheet Questions
B3: when are the peak hours
B4: what happen with the people that can`t fit in the bus?
B5: what happen if we cant not fit all the passengers, what is the associted lost cost of leaving these people?
B6: how long does it take for a bus for a full round trip?
B7: what do we want to optimize? The number of drivers? Number of buses?? | L7: little law
L8: https://en.wikipedia.org/wiki/Little%27s_law
L11: 4 hours the whole periord of time7
L12: avergae speed and distance
L15: infinite number of drivers
L17: the time will be less than an hpur
L19: number of buses per route
L20: little law
L21: l=lw
L22: number of passengers in a route
L23: L number os passengers
L24: lambda is rate
L25: w is given
... L29: that 15 is going to be the time between buses
